Workbook

Sheet Q
D1: AKDOGAN SPRING 2026 EXAM
D2: Balance sheet | G2: Income statement data points
D3: Assets | G3: A. Overnight position | J3: Credits | K3: Questions - Your cells MUST show the formulas | L3: Answer
D4: Overnight | E4: 17500 | G4: Interest income/loss | H4: 0 | K4: 1. Construct your P&L first. Next, calculate and report ($)
D5: Marketable securities | E5: 340245 | G5: B. Securities business | J5: 9 | K5: 1.1. Non interest income | L5: =A!E22 -> 28569.95
D6: HTM | E6: 252679 | G6: Interest income on HTM | H6: 7580.37 | J6: 9 | K6: 1.2. Bank revenues | L6: =A!E23 -> 81088.54
D7: Trading book | E7: 87566 | G7: Other interest income | H7: 1751.32 | J7: 9 | K7: 1.3. Earnings before taxes | L7: =A!E24 -> 56532.63
D8: Customer loans | E8: 897370 | G8: Trading gains | H8: 0 | J8: 9 | K8: 1.4. Net income | L8: =A!E25 -> 45251.104
D9: Enterprise | E9: 567600 | G9: Operating expense | H9: -340.245 | K9: 2. Calculate and report (%)
D10: Consumer | E10: 329770 | G10: Risk cost | H10: 0 | J10: 8 | K10: 2.1. Net interest margin | L10: =A!E27 -> 3.8004762
D11: Equity participations | E11: 47880 | G11: C. Enterprise loan assets | J11: 8 | K11: 2.2. Noninterest margin | L11: =A!E28 -> 2.0674472
D12: FinTech | E12: 34980 | G12: Interest income | H12: 28380 | J12: 8 | K12: 2.3. Yield on investment securities | L12: =A!E30 -> 2.7426384
D13: Gas Station Enterprise | E13: 12900 | G13: Noninterest income | H13: 17028 | J13: 8 | K13: 2.4. Enterprise loan yield | L13: =A!E32 -> 5
D14: Other core assets | E14: 78900 | G14: Operating expense | H14: -11352 | J14: 8 | K14: 2.5. Yield on wholesale funding | L14: =A!E33 -> 1.6263887
D15: Assets Total | E15: 1381895 | G15: Risk cost | H15: -1986.6 | J15: 12 | K15: 2.6. Return on Core Equity | L15: =A!E34 -> 36.327326
D16: Liabilities and equity | G16: D. Consumer loan assets | J16: 12 | K16: 2.7. Return on Non-core Equity | L16: =A!E35 -> 3.2945736
D17: Interest bearing liabilities | G17: Interest income | H17: 23083.9
D18: Overnight | E18: 17500 | G18: Noninterest income | H18: 11541.95
D19: Bonds issued | E19: 97890 | G19: Operating expense | H19: -9893.1
D20: Syndicated loans | E20: 327777 | G20: Risk cost | H20: -1483.965
D21: Deposits | E21: 749234 | G21: E. Breakdown of interest expense
D22: Other liabilities | E22: 53199 | G22: Bonds issued | H22: -1231
D23: Shareholders Equity | E23: 136295 | G23: Syndicated loans | H23: -5692
D24: Liabilities and equity total | E24: 1381895 | G24: Deposits | H24: -1354
G25: F. Equity participations
G26: FinTech dividend income | H26: 0
G27: Noncore dividend income | H27: 500
G28: Operating expense | H28: 0
G29: Risk cost | H29: 0
G30: G. Tax rates
G31: Corporate income tax | H31: 0.2
G32: Taxes on gains and dividends | H32: 0.15

Sheet A
A2: ANSWERS
A5: $M | B5: 2026 | D5: $M | E5: 2026
A6: Overnight | B6: =Q!E4 -> 17500 | D6: Interest income | E6: =SUM(B29+B31+B32+B37+B42) -> 60795.59
A7: Marketable securities | B7: =Q!E5 -> 340245 | D7: Interest expense | E7: =SUM(B47:B49) -> -8277
A8: HTM | B8: =Q!E6 -> 252679 | D8: Net interest income | E8: =E6+E7 -> 52518.59
A9: Trading book | B9: =Q!E7 -> 87566 | D9: Non-interest income | E9: =SUM(B33+B38+B43+B51) -> 28569.95
A10: Customer loans | B10: =Q!E8 -> 897370 | D10: Bank revenues | E10: =E8+E9 -> 81088.54
A11: Enterprise loans | B11: =Q!E9 -> 567600 | D11: OPEX | E11: =SUM(B34+B39+B44+B53) -> -21585.345
A12: Consumer loans | B12: =Q!E10 -> 329770 | D12: Operating income | E12: =E10+E11 -> 59503.195
A13: Equity participations | B13: =Q!E11 -> 47880 | D13: CoR | E13: =SUM(B35+B40+B45+B54) -> -3470.565
A14: FinTech equity | B14: =Q!E12 -> 34980 | D14: Non-core income | E14: =B52 -> 500
A15: Non-core equity | B15: =Q!E13 -> 12900 | D15: EBT | E15: =SUM(E12+E13+E14) -> 56532.63
A16: Other core assets | B16: =Q!E14 -> 78900 | D16: Corporate tax | E16: =-(E15-E14)*B24 -> -11206.526
A17: Total assets | B17: =Q!E15 -> 1381895 | D17: Taxes on dividends | E17: =-E14*B25 -> -75
A18: overnight | B18: =Q!E18 -> 17500 | D18: Total tax | E18: =E16+E17 -> -11281.526
A19: Bonds issued | B19: =Q!E19 -> 97890 | D19: Net income | E19: =E15+E18 -> 45251.104
A20: Syndicated loans | B20: =Q!E20 -> 327777
A21: Deposits | B21: =Q!E21 -> 749234 | D21: Questions - Answers | E21: 2026
A22: Other liabilities | B22: =Q!E22 -> 53199 | D22: 1.1. Non interest income | E22: =E9 -> 28569.95
A23: Shareholders Equity | B23: =Q!E23 -> 136295 | D23: 1.2. Bank revenues | E23: =E10 -> 81088.54
A24: Corporate income tax | B24: =Q!H31 -> 0.2 | D24: 1.3. Earnings before taxes | E24: =E15 -> 56532.63
A25: Taxes on gains/dividends | B25: =Q!H32 -> 0.15 | D25: 1.4. Net income | E25: =E19 -> 45251.104
A27: Income statement data | B27: 2026 | D27: 2.1. Net interest margin | E27: =E8/B17*100 -> 3.8004762
A28: a.overnight position | D28: 2.2. Noninterest margin | E28: =E9/B17*100 -> 2.0674472
A29: Overnight interest income/loss | B29: =Q!H4 -> 0
A30: b.securities business | D30: 2.3. Yield on investment securities | E30: =SUM(B31:B32)/B7*100 -> 2.7426384
A31: HTM interest income | B31: =Q!H6 -> 7580.37
A32: Other securities interest income | B32: =Q!H7 -> 1751.32 | D32: 2.4. Enterprise loan yield | E32: =B37/B11*100 -> 5
A33: Trading gains | B33: =Q!H8 -> 0 | D33: 2.5. Yield on wholesale funding | E33: =-SUM(B47:B48)/(B19+B20)*100 -> 1.6263887
A34: Securities operating expense | B34: =Q!H9 -> -340.245 | D34: 2.6. Return on Core Equity | E34: =(E15-E14+E16)/(B23-B15)*100 -> 36.327326
A35: risk cost | B35: =Q!H10 -> 0 | D35: 2.7. Return on Non-core Equity | E35: =(E14+E17)/B15*100 -> 3.2945736
A36: c.enterprise loan assets:
A37: Enterprise loan interest income | B37: =Q!H12 -> 28380
A38: Enterprise noninterest income | B38: =Q!H13 -> 17028
A39: Enterprise operating expense | B39: =Q!H14 -> -11352
A40: Enterprise risk cost | B40: =Q!H15 -> -1986.6
A41: d.consumer loan assets
A42: Consumer loan interest income | B42: =Q!H17 -> 23083.9
A43: Consumer noninterest income | B43: =Q!H18 -> 11541.95
A44: Consumer operating expense | B44: =Q!H19 -> -9893.1
...
